<mujoco model="mei">
    <default>
        <default class="mei">
        <!-- <geom friction="0.6" margin="0.001" condim="1"/>

        <joint axis="0 1 0" damping="1" armature="0.01" frictionloss="0.2"/> -->
        <joint damping="0.001" armature="0.01" frictionloss="0.1"/>
        <default class="abduction">
            <position forcerange="-23.7 23.7" ctrlrange="-1.00356 1.00356"/>
        </default>
        <default class="hip">
            <position forcerange="-23.7 23.7" ctrlrange="-0.567232 4.93056"/>
        </default>
        <default class="knee">
            <position forcerange="-35.55 35.55" ctrlrange="-2.7227 -0.83776"/>
        </default>

        <default class="motorV">
            <velocity ctrlrange="-30 30"/>
        </default>
        <default class="motorT">
            <motor gear="1" ctrllimited="true" ctrlrange="-23.7 23.7"/>
        </default>
        <default class="motorVc">
            <velocity ctrlrange="-20 20"/>
        </default>
        <default class="motorTc">
            <motor gear="1" ctrllimited="true" ctrlrange="-35.5 35.5"/>
        </default>

        <default class="visual">
            <geom type="mesh" contype="0" conaffinity="0" group="2" />
        </default>
        <default class="collision"><!-- 碰撞 -->
            <geom group="3" mass="0" type="sphere"/>
        </default>
        <site size="0.001" rgba="0.5 0.5 0.5 0.3" group="4"/>
        </default>
    </default>

    <!-- <extension>
        <plugin plugin="mujoco.sensor.ray_caster" />
        <plugin plugin="mujoco.sensor.ray_caster_camera" />
        <plugin plugin="mujoco.sensor.ray_caster_lidar" />
    </extension> -->

    <compiler angle="radian" meshdir="../meshes/" />
    <size njmax="500" nconmax="100" />
    <asset>
        <mesh name="base" file="base.STL" />
        <mesh name="FL_hip" file="FL_hip.STL" />
        <mesh name="FL_thigh" file="FL_thigh.STL" />
        <mesh name="FL_calf" file="FL_calf.STL" />
        <mesh name="FL_foot" file="FL_foot.STL" />
        <mesh name="FR_hip" file="FR_hip.STL" />
        <mesh name="FR_thigh" file="FR_thigh.STL" />
        <mesh name="FR_calf" file="FR_calf.STL" />
        <mesh name="FR_foot" file="FR_foot.STL" />
        <mesh name="RL_hip" file="RL_hip.STL" />
        <mesh name="RL_thigh" file="RL_thigh.STL" />
        <mesh name="RL_calf" file="RL_calf.STL" />
        <mesh name="RL_foot" file="RL_foot.STL" />
        <mesh name="RR_hip" file="RR_hip.STL" />
        <mesh name="RR_thigh" file="RR_thigh.STL" />
        <mesh name="RR_calf" file="RR_calf.STL" />
        <mesh name="RR_foot" file="RR_foot.STL" />
    </asset>
    <worldbody>

        <body name="robot" pos="-1 0 0.42" quat="1 0 0 0" childclass="mei">
        <joint name="float_base" type="free"/>
        <inertial pos="0 0 0" quat="1 0 0 0" mass="4.87475244" diaginertia="0.01839234 0.05151497 0.06165645"/> 
        <geom  type="mesh" contype="0" conaffinity="0" group="1" rgba="0.898039 0.917647 0.929412 1" mesh="base" />
        <geom class="collision" size="0.136 0.107 0.058" type="box" rgba="0.898039 0.917647 0.929412 1" />
        <site name="imu" pos="0 0 0.056"/>
                <!-- <camera name="depth_cam"
            pos="1 1 1"        euler="0 0 0"
            fovy="79.3"
            mode="fixed"/> -->
        <camera name="RayCasterCamera" pos="0.27 0.0 -0.0" xyaxes="0 -1 0 0 0 1"/>
        <geom size="0.0125 0.049 0.0125" pos="0.27 0 0.03" type="box" rgba="0.0 0.0 0.0 1" />

        <body name="FR_hip" pos="0.1403 -0.0502 0">
            <inertial pos="0.0595071 0.00087962 8.074e-05" quat="0.504125 0.502541 0.496919 0.496369" mass="0.644204" diaginertia="0.00317449 0.00285293 0.000438798" />
            <joint name="FR_hip_joint" pos="0 0 0" axis="1 0 0" limited="true" range="-1.0036 1.0036" />
            <geom  type="mesh" contype="0" conaffinity="0" group="1" rgba="0.752941 0.752941 0.752941 1" mesh="FR_hip" />
            <geom class="collision" size="0.046 0.02" pos="0.06676 -0.08 0" quat="0.707107 0.707107 0 0" type="cylinder" rgba="0.752941 0.752941 0.752941 1" />
            <body name="FR_thigh" pos="0.0667563 -0.0201539 0">
                <inertial pos="-0.00211808 -0.0470524 -0.0217645" quat="0.950167 -0.309807 0.0346802 -0.000206141" mass="0.958557" diaginertia="0.00590221 0.00493252 0.00188799" />
                <joint name="FR_thigh_joint" pos="0 0 0" axis="0 1 0" limited="true" range="-0.56723 4.9306" />
                <geom  type="mesh" contype="0" conaffinity="0" group="1" rgba="0.792157 0.819608 0.933333 1" mesh="FR_thigh" />
                <geom class="collision" size="0.05 0.011 0.019" pos="-0.019 -0.0691 -0.1" quat="0.707107 0 0.707107 0" type="box" rgba="0.792157 0.819608 0.933333 1" />
                <body name="FR_calf" pos="0 -0.0694 -0.22">
                    <inertial pos="0.0102562 0 -0.142333" quat="0.706652 -0.0253594 -0.0253594 0.706652" mass="0.185505" diaginertia="0.00353873 0.00348962 7.08642e-05" />
                    <joint name="FR_calf_joint" pos="0 0 0" axis="0 1 0" limited="true" range="-2.618 -0.69813" />
                    <geom type="mesh" contype="0" conaffinity="0" group="1" rgba="0.792157 0.819608 0.933333 1" mesh="FR_calf" />
                    <geom class="collision" size="0.01 0.034" pos="0.009 0 -0.028" quat="0.988771 0 -0.149438 0" type="cylinder" rgba="0.792157 0.819608 0.933333 1" />
                    <geom class="collision" size="0.01 0.019" pos="0.029 0 -0.1" quat="0.990901 0 -0.13459 0" type="cylinder" rgba="0.792157 0.819608 0.933333 1" />
                    <geom class="collision" size="0.0125 0.02" pos="0.031 0 -0.16" quat="0.998488 0 0.0549723 0" type="cylinder" rgba="0.792157 0.819608 0.933333 1" />
                    <geom pos="-0.00538771 0 -0.219021" type="mesh" contype="0" conaffinity="0" group="1" rgba="0.792157 0.819608 0.933333 1" mesh="FR_foot" />
                    <geom class="collision" size="0.02149" pos="0.0106123 0 -0.204021" rgba="0.792157 0.819608 0.933333 1" />
                    <site name="FR" size="0.02149" pos="0.0106123 0 -0.204021" group ="4"/>
                </body>
            </body>
        </body>


        <body name="FL_hip" pos="0.1403 0.0498 0">
            <inertial pos="0.0595071 0.00087962 -8.074e-05" quat="0.496919 0.496369 0.504125 0.502541" mass="0.644204" diaginertia="0.00317449 0.00285293 0.000438798" />
            <joint name="FL_hip_joint" pos="0 0 0" axis="1 0 0" limited="true" damping="0.1" armature="0.01" frictionloss="0.2" range="-1.0036 1.0036" />
            <geom type="mesh" contype="0" conaffinity="0" group="1" rgba="0.752941 0.752941 0.752941 1" mesh="FL_hip" />
            <geom class="collision" size="0.046 0.02" pos="0.06676 0.08 0" quat="0.707107 0.707107 0 0" type="cylinder" rgba="0.752941 0.752941 0.752941 1" />
            <body name="FL_thigh" pos="0.0667563 0.0201539 0">
                <inertial pos="-0.00211808 0.0470524 -0.0217645" quat="0.950167 0.309807 0.0346802 0.000206141" mass="0.958557" diaginertia="0.00590221 0.00493252 0.00188799" />
                <joint name="FL_thigh_joint" pos="0 0 0" axis="0 1 0" limited="true" range="-0.56723 4.9306" />
                <geom type="mesh" contype="0" conaffinity="0" group="1" rgba="0.698039 0.698039 0.698039 1" mesh="FL_thigh" />
                <geom class="collision" size="0.05 0.011 0.019" pos="-0.019 0.0691 -0.1" quat="0.707107 0 0.707107 0" type="box" rgba="0.698039 0.698039 0.698039 1" />
                <body name="FL_calf" pos="0 0.0694 -0.22">
                    <inertial pos="0.0102562 0 -0.142332" quat="0.706652 -0.0253595 -0.0253595 0.706652" mass="0.185505" diaginertia="0.00353873 0.00348961 7.08641e-05" />
                    <joint name="FL_calf_joint" pos="0 0 0" axis="0 1 0" limited="true" range="-2.618 -0.69813" />
                    <geom type="mesh" contype="0" conaffinity="0" group="1" rgba="0.686275 0.658824 0.639216 1" mesh="FL_calf" />
                    <geom class="collision" size="0.01 0.034" pos="0.009 0 -0.028" quat="0.988771 0 -0.149438 0" type="cylinder" rgba="0.686275 0.658824 0.639216 1" />
                    <geom class="collision" size="0.01 0.019" pos="0.029 0 -0.1" quat="0.990901 0 -0.13459 0" type="cylinder" rgba="0.686275 0.658824 0.639216 1" />
                    <geom class="collision" size="0.0125 0.02" pos="0.031 0 -0.16" quat="0.998488 0 0.0549723 0" type="cylinder" rgba="0.686275 0.658824 0.639216 1" />
                    <geom pos="-0.0053877 0 -0.21902" type="mesh" contype="0" conaffinity="0" group="1" rgba="0.686275 0.658824 0.639216 1" mesh="FL_foot" />
                    <geom class="collision" size="0.02149" pos="0.0106123 0 -0.20402" rgba="0.686275 0.658824 0.639216 1" />
                    <site name="FL" size="0.02149" pos="0.0106123 0 -0.204021" group ="4"/>
                </body>
            </body>
        </body>

        
        <body name="RR_hip" pos="-0.1403 -0.0502 0">
            <inertial pos="-0.0595071 -0.00087962 -8.074e-05" quat="0.496369 0.496919 0.502541 0.504125" mass="0.644204" diaginertia="0.00317449 0.00285293 0.000438798" />
            <joint name="RR_hip_joint" pos="0 0 0" axis="1 0 0" limited="true" range="-1.0036 1.0036" />
            <geom type="mesh" contype="0" conaffinity="0" group="1" rgba="1 1 1 1" mesh="RR_hip" />
            <geom class="collision" size="0.046 0.02" pos="-0.06676 -0.08 0" quat="0.707107 0.707107 0 0" type="cylinder" rgba="1 1 1 1" />
            <body name="RR_thigh" pos="-0.0667563 -0.0201539 0">
                <inertial pos="-0.00211808 -0.0470524 -0.0217645" quat="0.950167 -0.309807 0.0346802 -0.000206141" mass="0.958557" diaginertia="0.00590221 0.00493252 0.00188799" />
                <joint name="RR_thigh_joint" pos="0 0 0" axis="0 1 0" limited="true" range="-0.56723 4.9306" />
                <geom type="mesh" contype="0" conaffinity="0" group="1" rgba="0.792157 0.819608 0.933333 1" mesh="RR_thigh" />
                <geom class="collision" size="0.05 0.011 0.019" pos="-0.019 -0.0691 -0.1" quat="0.707107 0 0.707107 0" type="box" rgba="0.792157 0.819608 0.933333 1" />
                <body name="RR_calf" pos="0 -0.0694 -0.22">
                    <inertial pos="0.0102562 0 -0.142332" quat="0.706652 -0.0253595 -0.0253595 0.706652" mass="0.185505" diaginertia="0.00353873 0.00348961 7.08641e-05" />
                    <joint name="RR_calf_joint" pos="0 0 0" axis="0 1 0" limited="true" range="-2.618 -0.69813" />
                    <geom type="mesh" contype="0" conaffinity="0" group="1" rgba="0.792157 0.819608 0.933333 1" mesh="RR_calf" />
                    <geom class="collision" size="0.01 0.034" pos="0.009 0 -0.028" quat="0.988771 0 -0.149438 0" type="cylinder" rgba="0.792157 0.819608 0.933333 1" />
                    <geom class="collision" size="0.01 0.019" pos="0.029 0 -0.1" quat="0.990901 0 -0.13459 0" type="cylinder" rgba="0.792157 0.819608 0.933333 1" />
                    <geom class="collision" size="0.0125 0.02" pos="0.031 0 -0.16" quat="0.998488 0 0.0549723 0" type="cylinder" rgba="0.792157 0.819608 0.933333 1" />
                    <geom pos="-0.0053877 0 -0.21902" type="mesh" contype="0" conaffinity="0" group="1" rgba="0.79216 0.81961 0.93333 1" mesh="RR_foot" />
                    <geom class="collision" size="0.02149" pos="0.0106123 0 -0.20402" rgba="0.79216 0.81961 0.93333 1" />
                    <site name="RR" size="0.02149" pos="0.0106123 0 -0.204021" group ="4"/>
                </body>
            </body>
        </body>


        <body name="RL_hip" pos="-0.1403 0.0498 0">
            <inertial pos="-0.0595071 0.00087962 8.074e-05" quat="0.502541 0.504125 0.496369 0.496919" mass="0.644204" diaginertia="0.00317449 0.00285293 0.000438798" />
            <joint name="RL_hip_joint" pos="0 0 0" axis="1 0 0" limited="true" range="-1.0036 1.0036" />
            <geom type="mesh" contype="0" conaffinity="0" group="1" rgba="0.752941 0.752941 0.752941 1" mesh="RL_hip" />
            <geom class="collision" size="0.046 0.02" pos="-0.06676 0.08 0" quat="0.707107 0.707107 0 0" type="cylinder" rgba="0.752941 0.752941 0.752941 1" />
            <body name="RL_thigh" pos="-0.0667563 0.0201539 0">
                <inertial pos="-0.00211808 0.0470524 -0.0217645" quat="0.950167 0.309807 0.0346802 0.000206141" mass="0.958557" diaginertia="0.00590221 0.00493252 0.00188799" />
                <joint name="RL_thigh_joint" pos="0 0 0" axis="0 1 0" limited="true" range="-0.56723 4.9306" />
                <geom type="mesh" contype="0" conaffinity="0" group="1" rgba="0.698039 0.698039 0.698039 1" mesh="RL_thigh" />
                <geom class="collision" size="0.05 0.011 0.019" pos="-0.019 0.0691 -0.1" quat="0.707107 0 0.707107 0" type="box" rgba="0.698039 0.698039 0.698039 1" />
                <body name="RL_calf" pos="0 0.0694 -0.22">
                    <inertial pos="0.0102562 0 -0.142333" quat="0.706652 -0.0253594 -0.0253594 0.706652" mass="0.185505" diaginertia="0.00353873 0.00348962 7.08642e-05" />
                    <joint name="RL_calf_joint" pos="0 0 0" axis="0 1 0" limited="true" range="-2.618 -0.69813" />
                    <geom type="mesh" contype="0" conaffinity="0" group="1" rgba="0.898039 0.917647 0.929412 1" mesh="RL_calf" />
                    <geom class="collision" size="0.01 0.034" pos="0.009 0 -0.028" quat="0.988771 0 -0.149438 0" type="cylinder" rgba="0.898039 0.917647 0.929412 1" />
                    <geom class="collision" size="0.01 0.019" pos="0.029 0 -0.1" quat="0.990901 0 -0.13459 0" type="cylinder" rgba="0.898039 0.917647 0.929412 1" />
                    <geom class="collision" size="0.0125 0.02" pos="0.031 0 -0.16" quat="0.998488 0 0.0549723 0" type="cylinder" rgba="0.898039 0.917647 0.929412 1" />
                    <geom pos="-0.00538771 0 -0.219021" type="mesh" contype="0" conaffinity="0" group="1" rgba="0.686275 0.658824 0.639216 1" mesh="RL_foot" />
                    <geom class="collision" size="0.02149" pos="0.0106123 0 -0.204021" rgba="0.686275 0.658824 0.639216 1" />
                    <site name="RL" size="0.02149" pos="0.0106123 0 -0.204021" group ="4"/>
                </body>
            </body>
        </body>


       </body> 
    </worldbody>

    <actuator>      
        <position class="abduction" name="FR1" joint="FR_hip_joint"/>
        <position class="hip" name="FR2" joint="FR_thigh_joint"/>
        <position class="knee" name="FR3" joint="FR_calf_joint"/>
        <position class="abduction" name="FL1" joint="FL_hip_joint"/>
        <position class="hip" name="FL2" joint="FL_thigh_joint"/>
        <position class="knee" name="FL3" joint="FL_calf_joint"/>
        <position class="abduction" name="RR1" joint="RR_hip_joint"/>
        <position class="hip" name="RR2" joint="RR_thigh_joint"/>
        <position class="knee" name="RR3" joint="RR_calf_joint"/>
        <position class="abduction" name="RL1" joint="RL_hip_joint"/>
        <position class="hip" name="RL2" joint="RL_thigh_joint"/>
        <position class="knee" name="RL3" joint="RL_calf_joint"/>
        
        <velocity class="motorV" name="FR_hipV" joint="FR_hip_joint"/>
        <velocity class="motorV" name="FR_thighV" joint="FR_thigh_joint"/>
        <velocity class="motorVc" name="FR_calfV" joint="FR_calf_joint"/>
        <velocity class="motorV" name="FL_hipV" joint="FL_hip_joint"/>
        <velocity class="motorV" name="FL_thighV" joint="FL_thigh_joint"/>
        <velocity class="motorVc" name="FL_calfV" joint="FL_calf_joint"/>
        <velocity class="motorV" name="RR_hipV" joint="RR_hip_joint"/>
        <velocity class="motorV" name="RR_thighV" joint="RR_thigh_joint"/>
        <velocity class="motorVc" name="RR_calfV" joint="RR_calf_joint"/>
        <velocity class="motorV" name="RL_hipV" joint="RL_hip_joint"/>
        <velocity class="motorV" name="RL_thighV" joint="RL_thigh_joint"/>
        <velocity class="motorVc" name="RL_calfV" joint="RL_calf_joint"/>


        <motor name="FR_hip_joint" joint="FR_hip_joint" gear="1" ctrllimited="true" ctrlrange="-23.7 23.7"/>
        <motor name="FR_thigh_joint" joint="FR_thigh_joint" gear="1" ctrllimited="true" ctrlrange="-23.7 23.7"/>
        <motor name="FR_calf_joint" joint="FR_calf_joint" gear="1" ctrllimited="true" ctrlrange="-35.5 35.5"/>
        <motor name="FL_hip_joint" joint="FL_hip_joint" gear="1" ctrllimited="true" ctrlrange="-23.7 23.7"/>
        <motor name="FL_thigh_joint" joint="FL_thigh_joint" gear="1" ctrllimited="true" ctrlrange="-23.7 23.7"/>
        <motor name="FL_calf_joint" joint="FL_calf_joint" gear="1" ctrllimited="true" ctrlrange="-35.5 35.5"/>

        <motor name="RR_hip_joint" joint="RR_hip_joint" gear="1" ctrllimited="true" ctrlrange="-23.7 23.7"/>
        <motor name="RR_thigh_joint" joint="RR_thigh_joint" gear="1" ctrllimited="true" ctrlrange="-23.7 23.7"/>
        <motor name="RR_calf_joint" joint="RR_calf_joint" gear="1" ctrllimited="true" ctrlrange="-35.5 35.5"/>
        <motor name="RL_hip_joint" joint="RL_hip_joint" gear="1" ctrllimited="true" ctrlrange="-23.7 23.7"/>
        <motor name="RL_thigh_joint" joint="RL_thigh_joint" gear="1" ctrllimited="true" ctrlrange="-23.7 23.7"/>
        <motor name="RL_calf_joint" joint="RL_calf_joint" gear="1" ctrllimited="true" ctrlrange="-35.5 35.5"/>
    </actuator>
    <sensor>
        <jointpos name='FR_hip_joint_p'  joint='FR_hip_joint'/>
        <jointpos name='FR_thigh_joint_p'  joint='FR_thigh_joint'/>
        <jointpos name='FR_calf_joint_p'  joint='FR_calf_joint'/>
        <jointpos name='FL_hip_joint_p'  joint='FL_hip_joint'/>
        <jointpos name='FL_thigh_joint_p'  joint='FL_thigh_joint'/>
        <jointpos name='FL_calf_joint_p'  joint='FL_calf_joint'/>
        <jointpos name='RR_hip_joint_p'  joint='RR_hip_joint'/>
        <jointpos name='RR_thigh_joint_p'  joint='RR_thigh_joint'/>
        <jointpos name='RR_calf_joint_p'  joint='RR_calf_joint'/>
        <jointpos name='RL_hip_joint_p'  joint='RL_hip_joint'/>
        <jointpos name='RL_thigh_joint_p'  joint='RL_thigh_joint'/>
        <jointpos name='RL_calf_joint_p'  joint='RL_calf_joint'/>

        <jointvel name='FR_hip_joint_v'  joint='FR_hip_joint'/>
        <jointvel name='FR_thigh_joint_v'  joint='FR_thigh_joint'/>
        <jointvel name='FR_calf_joint_v'  joint='FR_calf_joint'/>
        <jointvel name='FL_hip_joint_v'  joint='FL_hip_joint'/>
        <jointvel name='FL_thigh_joint_v'  joint='FL_thigh_joint'/>
        <jointvel name='FL_calf_joint_v'  joint='FL_calf_joint'/>
        <jointvel name='RR_hip_joint_v'  joint='RR_hip_joint'/>
        <jointvel name='RR_thigh_joint_v'  joint='RR_thigh_joint'/>
        <jointvel name='RR_calf_joint_v'  joint='RR_calf_joint'/>
        <jointvel name='RL_hip_joint_v'  joint='RL_hip_joint'/>
        <jointvel name='RL_thigh_joint_v'  joint='RL_thigh_joint'/>
        <jointvel name='RL_calf_joint_v'  joint='RL_calf_joint'/>

        <framequat name="imu_quat" objtype="site" objname="imu" />
        <gyro name="imu_gyro" site="imu" />
        <accelerometer name="imu_acc" site="imu" />
        
        <framepos name="frame_pos" objtype="site" objname="imu" />
        <framelinvel name="frame_vel" objtype="site" objname="imu" />


        <!-- <touch name="foot_contact_sensor_1" site="FR"/>
        <touch name="foot_contact_sensor_2" site="FL"/>
        <touch name="foot_contact_sensor_3" site="RR"/>
        <touch name="foot_contact_sensor_4" site="RL"/> -->

        <!-- <plugin name="raycastercamera" plugin="mujoco.sensor.ray_caster_camera" objtype="camera" objname="RayCasterCamera">
            <config key="focal_length" value="11.041" />
            <config key="horizontal_aperture" value="20.955" />
            <config key="vertical_aperture" value="12.240" />
            <config key="size" value="106 60" />
            <config key="dis_range" value="0.01 2.0" />
            <config key="sensor_data_types" value="image inv_image data" /> -->

            <!-- <config key="sensor_data_types" value="image inv_image pos_w pos_b" /> -->
            <!-- <config key="compute_time_log" value="1" /> -->
            <!-- <config key="draw_deep_ray" value="1 5 1 1 0.2 0.5 1" /> -->
            <!-- <config key="draw_deep_ray_ids" value="0 10 1 0 0 0.5 1 2 3 4 5 30" /> -->
            <!-- <config key="draw_deep" value="2 5 0 1 0" /> -->
            <!-- <config key="draw_hip_point" value="1 0.02" /> -->

            <!-- <config key="noise_type" value="uniform" />
            <config key="noise_cfg" value="-0.1 0.1 1" />
            <config key="geomgroup" value="0 0 1 0 0 0 "/>
        </plugin> -->


    </sensor>

</mujoco>
