<mujoco model="zof_deploy_from_urdf">
  <compiler angle="radian" meshdir="../meshes/"/>

  <visual>
    <headlight diffuse="0.6 0.6 0.6" ambient="0.3 0.3 0.3" specular="0 0 0"/>
  </visual>

  <asset>
    <texture type="2d" name="groundplane" builtin="checker" mark="edge"
             rgb1="0.2 0.3 0.4" rgb2="0.1 0.2 0.3" markrgb="0.8 0.8 0.8" width="300" height="300"/>
    <material name="groundplane" texture="groundplane" texuniform="true" texrepeat="5 5" reflectance="0.2"/>
    <mesh name="base" file="../meshes/base.STL"/>
    <mesh name="FL_hip" file="../meshes/FL_hip.STL"/>
    <mesh name="FL_thigh" file="../meshes/FL_thigh.STL"/>
    <mesh name="FL_calf" file="../meshes/FL_calf.STL"/>
    <mesh name="FL_foot" file="../meshes/FL_foot.STL"/>
    <mesh name="FR_hip" file="../meshes/FR_hip.STL"/>
    <mesh name="FR_thigh" file="../meshes/FR_thigh.STL"/>
    <mesh name="FR_calf" file="../meshes/FR_calf.STL"/>
    <mesh name="FR_foot" file="../meshes/FR_foot.STL"/>
    <mesh name="RL_hip" file="../meshes/RL_hip.STL"/>
    <mesh name="RL_thigh" file="../meshes/RL_thigh.STL"/>
    <mesh name="RL_calf" file="../meshes/RL_calf.STL"/>
    <mesh name="RL_foot" file="../meshes/RL_foot.STL"/>
    <mesh name="RR_hip" file="../meshes/RR_hip.STL"/>
    <mesh name="RR_thigh" file="../meshes/RR_thigh.STL"/>
    <mesh name="RR_calf" file="../meshes/RR_calf.STL"/>
    <mesh name="RR_foot" file="../meshes/RR_foot.STL"/>
  </asset>

  <worldbody>
    <light pos="0 0 3" dir="0 0 -1" directional="true"/>
    <geom name="floor" type="plane" size="0 0 0.05" material="groundplane" friction="0.6 0.02 0.001"/>
    <body name="base">
      <inertial pos="0.00757956 -0.0002 -0.00254703" quat="-0.000168829 0.709518 -8.20306e-06 0.704687" mass="4.87475" diaginertia="0.0616585 0.051515 0.0183903"/>
      <joint name="float_base" type="free" limited="false" actuatorfrclimited="false"/>
      <geom type="mesh" contype="0" conaffinity="0" group="1" density="0" rgba="0.898039 0.917647 0.929412 1" mesh="base"/>
      <geom size="0.136 0.107 0.058" type="box" rgba="0.898039 0.917647 0.929412 1"/>
      <site name="imu" pos="0 0 0" size="0.01"/>
      <body name="FL_hip" pos="0.1403 0.0498 0">
        <inertial pos="0.0595071 0.00087962 -8.074e-05" quat="0.496919 0.496369 0.504125 0.502541" mass="0.644204" diaginertia="0.00317449 0.00285293 0.000438798"/>
        <joint name="FL_hip_joint" pos="0 0 0" axis="1 0 0" range="-1.0036 1.0036" actuatorfrcrange="-23.7 23.7"/>
        <geom type="mesh" contype="0" conaffinity="0" group="1" density="0" rgba="0.752941 0.752941 0.752941 1" mesh="FL_hip"/>
        <geom size="0.046 0.02" pos="0.06676 0.08 0" quat="0.707107 0.707107 0 0" type="cylinder" rgba="0.752941 0.752941 0.752941 1"/>
        <body name="FL_thigh" pos="0.0667563 0.0201539 0">
          <inertial pos="-0.00211808 0.0470524 -0.0217645" quat="0.950167 0.309807 0.0346802 0.000206141" mass="0.958557" diaginertia="0.00590221 0.00493252 0.00188799"/>
          <joint name="FL_thigh_joint" pos="0 0 0" axis="0 1 0" range="-0.56723 4.9306" actuatorfrcrange="-23.7 23.7"/>
          <geom type="mesh" contype="0" conaffinity="0" group="1" density="0" rgba="0.698039 0.698039 0.698039 1" mesh="FL_thigh"/>
          <geom size="0.05 0.011 0.019" pos="-0.019 0.0691 -0.1" quat="0.707107 0 0.707107 0" type="box" rgba="0.698039 0.698039 0.698039 1"/>
          <body name="FL_calf" pos="0 0.0694 -0.22">
            <inertial pos="0.0102562 0 -0.142332" quat="0.706652 -0.0253595 -0.0253595 0.706652" mass="0.185505" diaginertia="0.00353873 0.00348961 7.08641e-05"/>
            <joint name="FL_calf_joint" pos="0 0 0" axis="0 1 0" range="-2.618 -0.69813" actuatorfrcrange="-35.55 35.55"/>
            <geom type="mesh" contype="0" conaffinity="0" group="1" density="0" rgba="0.686275 0.658824 0.639216 1" mesh="FL_calf"/>
            <geom size="0.01 0.034" pos="0.009 0 -0.028" quat="0.988771 0 -0.149438 0" type="cylinder" rgba="0.686275 0.658824 0.639216 1"/>
            <geom size="0.01 0.019" pos="0.029 0 -0.1" quat="0.990901 0 -0.13459 0" type="cylinder" rgba="0.686275 0.658824 0.639216 1"/>
            <geom size="0.0125 0.02" pos="0.031 0 -0.16" quat="0.998488 0 0.0549723 0" type="cylinder" rgba="0.686275 0.658824 0.639216 1"/>
            <geom pos="-0.0053877 0 -0.21902" quat="1 0 0 0" type="mesh" contype="0" conaffinity="0" group="1" density="0" rgba="0.686275 0.658824 0.639216 1" mesh="FL_foot"/>
            <geom size="0.02149" pos="0.0106123 0 -0.20402" rgba="0.686275 0.658824 0.639216 1"/>
          </body>
        </body>
      </body>
      <body name="FR_hip" pos="0.1403 -0.0502 0">
        <inertial pos="0.0595071 0.00087962 8.074e-05" quat="0.504125 0.502541 0.496919 0.496369" mass="0.644204" diaginertia="0.00317449 0.00285293 0.000438798"/>
        <joint name="FR_hip_joint" pos="0 0 0" axis="1 0 0" range="-1.0036 1.0036" actuatorfrcrange="-23.7 23.7"/>
        <geom type="mesh" contype="0" conaffinity="0" group="1" density="0" rgba="0.752941 0.752941 0.752941 1" mesh="FR_hip"/>
        <geom size="0.046 0.02" pos="0.06676 -0.08 0" quat="0.707107 0.707107 0 0" type="cylinder" rgba="0.752941 0.752941 0.752941 1"/>
        <body name="FR_thigh" pos="0.0667563 -0.0201539 0">
          <inertial pos="-0.00211808 -0.0470524 -0.0217645" quat="0.950167 -0.309807 0.0346802 -0.000206141" mass="0.958557" diaginertia="0.00590221 0.00493252 0.00188799"/>
          <joint name="FR_thigh_joint" pos="0 0 0" axis="0 1 0" range="-0.56723 4.9306" actuatorfrcrange="-23.7 23.7"/>
          <geom type="mesh" contype="0" conaffinity="0" group="1" density="0" rgba="0.792157 0.819608 0.933333 1" mesh="FR_thigh"/>
          <geom size="0.05 0.011 0.019" pos="-0.019 -0.0691 -0.1" quat="0.707107 0 0.707107 0" type="box" rgba="0.792157 0.819608 0.933333 1"/>
          <body name="FR_calf" pos="0 -0.0694 -0.22">
            <inertial pos="0.0102562 0 -0.142333" quat="0.706652 -0.0253594 -0.0253594 0.706652" mass="0.185505" diaginertia="0.00353873 0.00348962 7.08642e-05"/>
            <joint name="FR_calf_joint" pos="0 0 0" axis="0 1 0" range="-2.618 -0.69813" actuatorfrcrange="-35.55 35.55"/>
            <geom type="mesh" contype="0" conaffinity="0" group="1" density="0" rgba="0.792157 0.819608 0.933333 1" mesh="FR_calf"/>
            <geom size="0.01 0.034" pos="0.009 0 -0.028" quat="0.988771 0 -0.149438 0" type="cylinder" rgba="0.792157 0.819608 0.933333 1"/>
            <geom size="0.01 0.019" pos="0.029 0 -0.1" quat="0.990901 0 -0.13459 0" type="cylinder" rgba="0.792157 0.819608 0.933333 1"/>
            <geom size="0.0125 0.02" pos="0.031 0 -0.16" quat="0.998488 0 0.0549723 0" type="cylinder" rgba="0.792157 0.819608 0.933333 1"/>
            <geom pos="-0.00538771 0 -0.219021" quat="1 0 0 0" type="mesh" contype="0" conaffinity="0" group="1" density="0" rgba="0.792157 0.819608 0.933333 1" mesh="FR_foot"/>
            <geom size="0.02149" pos="0.0106123 0 -0.204021" rgba="0.792157 0.819608 0.933333 1"/>
          </body>
        </body>
      </body>
      <body name="RL_hip" pos="-0.1403 0.0498 0">
        <inertial pos="-0.0595071 0.00087962 8.074e-05" quat="0.502541 0.504125 0.496369 0.496919" mass="0.644204" diaginertia="0.00317449 0.00285293 0.000438798"/>
        <joint name="RL_hip_joint" pos="0 0 0" axis="1 0 0" range="-1.0036 1.0036" actuatorfrcrange="-23.7 23.7"/>
        <geom type="mesh" contype="0" conaffinity="0" group="1" density="0" rgba="0.752941 0.752941 0.752941 1" mesh="RL_hip"/>
        <geom size="0.046 0.02" pos="-0.06676 0.08 0" quat="0.707107 0.707107 0 0" type="cylinder" rgba="0.752941 0.752941 0.752941 1"/>
        <body name="RL_thigh" pos="-0.0667563 0.0201539 0">
          <inertial pos="-0.00211808 0.0470524 -0.0217645" quat="0.950167 0.309807 0.0346802 0.000206141" mass="0.958557" diaginertia="0.00590221 0.00493252 0.00188799"/>
          <joint name="RL_thigh_joint" pos="0 0 0" axis="0 1 0" range="-0.56723 4.9306" actuatorfrcrange="-23.7 23.7"/>
          <geom type="mesh" contype="0" conaffinity="0" group="1" density="0" rgba="0.698039 0.698039 0.698039 1" mesh="RL_thigh"/>
          <geom size="0.05 0.011 0.019" pos="-0.019 0.0691 -0.1" quat="0.707107 0 0.707107 0" type="box" rgba="0.698039 0.698039 0.698039 1"/>
          <body name="RL_calf" pos="0 0.0694 -0.22">
            <inertial pos="0.0102562 0 -0.142333" quat="0.706652 -0.0253594 -0.0253594 0.706652" mass="0.185505" diaginertia="0.00353873 0.00348962 7.08642e-05"/>
            <joint name="RL_calf_joint" pos="0 0 0" axis="0 1 0" range="-2.618 -0.69813" actuatorfrcrange="-35.55 35.55"/>
            <geom type="mesh" contype="0" conaffinity="0" group="1" density="0" rgba="0.898039 0.917647 0.929412 1" mesh="RL_calf"/>
            <geom size="0.01 0.034" pos="0.009 0 -0.028" quat="0.988771 0 -0.149438 0" type="cylinder" rgba="0.898039 0.917647 0.929412 1"/>
            <geom size="0.01 0.019" pos="0.029 0 -0.1" quat="0.990901 0 -0.13459 0" type="cylinder" rgba="0.898039 0.917647 0.929412 1"/>
            <geom size="0.0125 0.02" pos="0.031 0 -0.16" quat="0.998488 0 0.0549723 0" type="cylinder" rgba="0.898039 0.917647 0.929412 1"/>
            <geom pos="-0.00538771 0 -0.219021" quat="1 0 0 0" type="mesh" contype="0" conaffinity="0" group="1" density="0" rgba="0.686275 0.658824 0.639216 1" mesh="RL_foot"/>
            <geom size="0.02149" pos="0.0106123 0 -0.204021" rgba="0.686275 0.658824 0.639216 1"/>
          </body>
        </body>
      </body>
      <body name="RR_hip" pos="-0.1403 -0.0502 0">
        <inertial pos="-0.0595071 -0.00087962 -8.074e-05" quat="0.496369 0.496919 0.502541 0.504125" mass="0.644204" diaginertia="0.00317449 0.00285293 0.000438798"/>
        <joint name="RR_hip_joint" pos="0 0 0" axis="1 0 0" range="-1.0036 1.0036" actuatorfrcrange="-23.7 23.7"/>
        <geom type="mesh" contype="0" conaffinity="0" group="1" density="0" rgba="1 1 1 1" mesh="RR_hip"/>
        <geom size="0.046 0.02" pos="-0.06676 -0.08 0" quat="0.707107 0.707107 0 0" type="cylinder" rgba="1 1 1 1"/>
        <body name="RR_thigh" pos="-0.0667563 -0.0201539 0">
          <inertial pos="-0.00211808 -0.0470524 -0.0217645" quat="0.950167 -0.309807 0.0346802 -0.000206141" mass="0.958557" diaginertia="0.00590221 0.00493252 0.00188799"/>
          <joint name="RR_thigh_joint" pos="0 0 0" axis="0 1 0" range="-0.56723 4.9306" actuatorfrcrange="-23.7 23.7"/>
          <geom type="mesh" contype="0" conaffinity="0" group="1" density="0" rgba="0.792157 0.819608 0.933333 1" mesh="RR_thigh"/>
          <geom size="0.05 0.011 0.019" pos="-0.019 -0.0691 -0.1" quat="0.707107 0 0.707107 0" type="box" rgba="0.792157 0.819608 0.933333 1"/>
          <body name="RR_calf" pos="0 -0.0694 -0.22">
            <inertial pos="0.0102562 0 -0.142332" quat="0.706652 -0.0253595 -0.0253595 0.706652" mass="0.185505" diaginertia="0.00353873 0.00348961 7.08641e-05"/>
            <joint name="RR_calf_joint" pos="0 0 0" axis="0 1 0" range="-2.618 -0.69813" actuatorfrcrange="-35.55 35.55"/>
            <geom type="mesh" contype="0" conaffinity="0" group="1" density="0" rgba="0.792157 0.819608 0.933333 1" mesh="RR_calf"/>
            <geom size="0.01 0.034" pos="0.009 0 -0.028" quat="0.988771 0 -0.149438 0" type="cylinder" rgba="0.792157 0.819608 0.933333 1"/>
            <geom size="0.01 0.019" pos="0.029 0 -0.1" quat="0.990901 0 -0.13459 0" type="cylinder" rgba="0.792157 0.819608 0.933333 1"/>
            <geom size="0.0125 0.02" pos="0.031 0 -0.16" quat="0.998488 0 0.0549723 0" type="cylinder" rgba="0.792157 0.819608 0.933333 1"/>
            <geom pos="-0.0053877 0 -0.21902" quat="1 0 0 0" type="mesh" contype="0" conaffinity="0" group="1" density="0" rgba="0.79216 0.81961 0.93333 1" mesh="RR_foot"/>
            <geom size="0.02149" pos="0.0106123 0 -0.20402" rgba="0.79216 0.81961 0.93333 1"/>
          </body>
        </body>
      </body>
    </body>
  </worldbody>
  <actuator>
    <motor name="FL_hip_joint" joint="FL_hip_joint" gear="1" ctrllimited="true" ctrlrange="-23.7 23.7"/>
    <motor name="FL_thigh_joint" joint="FL_thigh_joint" gear="1" ctrllimited="true" ctrlrange="-23.7 23.7"/>
    <motor name="FL_calf_joint" joint="FL_calf_joint" gear="1" ctrllimited="true" ctrlrange="-35.55 35.55"/>
    <motor name="FR_hip_joint" joint="FR_hip_joint" gear="1" ctrllimited="true" ctrlrange="-23.7 23.7"/>
    <motor name="FR_thigh_joint" joint="FR_thigh_joint" gear="1" ctrllimited="true" ctrlrange="-23.7 23.7"/>
    <motor name="FR_calf_joint" joint="FR_calf_joint" gear="1" ctrllimited="true" ctrlrange="-35.55 35.55"/>
    <motor name="RL_hip_joint" joint="RL_hip_joint" gear="1" ctrllimited="true" ctrlrange="-23.7 23.7"/>
    <motor name="RL_thigh_joint" joint="RL_thigh_joint" gear="1" ctrllimited="true" ctrlrange="-23.7 23.7"/>
    <motor name="RL_calf_joint" joint="RL_calf_joint" gear="1" ctrllimited="true" ctrlrange="-35.55 35.55"/>
    <motor name="RR_hip_joint" joint="RR_hip_joint" gear="1" ctrllimited="true" ctrlrange="-23.7 23.7"/>
    <motor name="RR_thigh_joint" joint="RR_thigh_joint" gear="1" ctrllimited="true" ctrlrange="-23.7 23.7"/>
    <motor name="RR_calf_joint" joint="RR_calf_joint" gear="1" ctrllimited="true" ctrlrange="-35.55 35.55"/>
  </actuator>

  <sensor>
    <framequat name="imu_quat" objtype="site" objname="imu"/>
    <gyro name="imu_gyro" site="imu"/>
  </sensor>

</mujoco>
